<sdf version='1.11'>
  
  <model name='rover'>

    <include>
      <uri>robot-localization/sdf/rover_sensor.sdf</uri>
    </include>

    <plugin name="gz::sim::systems::DiffDrive" filename="gz-sim-diff-drive-system">
      <left_joint>rear_left_joint</left_joint>
      <right_joint>rear_right_joint</right_joint>
      <wheel_separation>0.5</wheel_separation>
      <wheel_radius>0.2</wheel_radius>
      <topic>cmd_vel</topic>
    </plugin>

    <link name='chassis'>
      <inertial>
        <pose >0 0 0 0 0 0</pose>
        <mass>1.14395</mass>
        <inertia>
          <ixx>0.095328999999999997</ixx>
          <ixy>0</ixy>
          <ixz>0</ixz>
          <iyy>0.38131700000000002</iyy>
          <iyz>0</iyz>
          <izz>0.47664600000000001</izz>
        </inertia>
      </inertial>
      <collision name='chassis_collision'>
        <pose>0 0 0 0 0 0</pose>
        <geometry>
          <box>
            <size>1 0.5 0.25</size>
          </box>
        </geometry>
      </collision>
      <visual name='chassis_visual'>
        <pose>0 0 0 0 0 0</pose>
        <geometry>
          <box>
            <size>1 0.5 0.25</size>
          </box>
        </geometry>
        <material>
          <diffuse>0 0 1 1</diffuse>
          <ambient>0 0 1 1</ambient>
        </material>
      </visual>
    </link>
    <joint name='front_left_joint' type='revolute'>
      <pose relative_to='chassis'>0.5 0.20000000000000002 0 0 0 0</pose>
      <parent>chassis</parent>
      <child>front_left_wheel</child>
      <axis>
        <xyz>0 1 0</xyz>
        <limit>
          <lower>-inf</lower>
          <upper>inf</upper>
        </limit>
        <dynamics>
          <spring_reference>0</spring_reference>
          <spring_stiffness>0</spring_stiffness>
        </dynamics>
      </axis>
    </joint>
    <link name='front_left_wheel'>
      <pose relative_to='front_left_joint'>0 0 0 0 0 0</pose>
      <inertial>
        <pose>0 0 0 0 0 0</pose>
        <mass>1</mass>
        <inertia>
          <ixx>0.043333000000000003</ixx>
          <ixy>0</ixy>
          <ixz>0</ixz>
          <iyy>0.043333000000000003</iyy>
          <iyz>0</iyz>
          <izz>0.080000000000000002</izz>
        </inertia>
      </inertial>
      <collision name='front_left_wheel_collision'>
        <pose>0 0 0 1.5708 0 0</pose>
        <geometry>
          <cylinder>
            <length>0.10000000000000001</length>
            <radius>0.20000000000000002</radius>
          </cylinder>
        </geometry>
      </collision>
      <visual name='front_left_wheel_visual'>
        <pose>0 0 0 1.5708 0 0</pose>
        <geometry>
          <cylinder>
            <length>0.10000000000000001</length>
            <radius>0.20000000000000002</radius>
          </cylinder>
        </geometry>
        <material>
          <diffuse>0 1 0 1</diffuse>
          <ambient>0 1 0 1</ambient>
        </material>
      </visual>
    </link>
    <joint name='front_right_joint' type='revolute'>
      <pose relative_to='chassis'>0.5 -0.20000000000000002 0 0 0 0</pose>
      <parent>chassis</parent>
      <child>front_right_wheel</child>
      <axis>
        <xyz>0 1 0</xyz>
        <limit>
          <lower>-inf</lower>
          <upper>inf</upper>
        </limit>
        <dynamics>
          <spring_reference>0</spring_reference>
          <spring_stiffness>0</spring_stiffness>
        </dynamics>
      </axis>
    </joint>
    <link name='front_right_wheel'>
      <pose relative_to='front_right_joint'>0 0 0 0 0 0</pose>
      <inertial>
        <pose>0 0 0 0 0 0</pose>
        <mass>1</mass>
        <inertia>
          <ixx>0.043333000000000003</ixx>
          <ixy>0</ixy>
          <ixz>0</ixz>
          <iyy>0.043333000000000003</iyy>
          <iyz>0</iyz>
          <izz>0.080000000000000002</izz>
        </inertia>
      </inertial>
      <collision name='front_right_wheel_collision'>
        <pose>0 0 0 1.5708 0 0</pose>
        <geometry>
          <cylinder>
            <length>0.10000000000000001</length>
            <radius>0.20000000000000002</radius>
          </cylinder>
        </geometry>
      </collision>
      <visual name='front_right_wheel_visual'>
        <pose>0 0 0 1.5708 0 0</pose>
        <geometry>
          <cylinder>
            <length>0.10000000000000001</length>
            <radius>0.20000000000000002</radius>
          </cylinder>
        </geometry>
        <material>
          <diffuse>0 1 0 1</diffuse>
          <ambient>0 1 0 1</ambient>
        </material>
      </visual>
    </link>
    <joint name='rear_left_joint' type='revolute'>
      <pose relative_to='chassis'>-0.5 0.20000000000000002 0 0 0 0</pose>
      <parent>chassis</parent>
      <child>rear_left_wheel</child>
      <axis>
        <xyz>0 1 0</xyz>
        <limit>
          <lower>-inf</lower>
          <upper>inf</upper>
        </limit>
        <dynamics>
          <spring_reference>0</spring_reference>
          <spring_stiffness>0</spring_stiffness>
        </dynamics>
      </axis>
    </joint>
    <link name='rear_left_wheel'>
      <pose relative_to='rear_left_joint'>0 0 0 0 0 0</pose>
      <inertial>
        <pose>0 0 0 0 0 0</pose>
        <mass>1</mass>
        <inertia>
          <ixx>0.043333000000000003</ixx>
          <ixy>0</ixy>
          <ixz>0</ixz>
          <iyy>0.043333000000000003</iyy>
          <iyz>0</iyz>
          <izz>0.080000000000000002</izz>
        </inertia>
      </inertial>
      <collision name='rear_left_wheel_collision'>
        <pose>0 0 0 1.5708 0 0</pose>
        <geometry>
          <cylinder>
            <length>0.10000000000000001</length>
            <radius>0.20000000000000002</radius>
          </cylinder>
        </geometry>
      </collision>
      <visual name='rear_left_wheel_visual'>
        <pose>0 0 0 1.5708 0 0</pose>
        <geometry>
          <cylinder>
            <length>0.10000000000000001</length>
            <radius>0.20000000000000002</radius>
          </cylinder>
        </geometry>
        <material>
          <diffuse>0 1 0 1</diffuse>
          <ambient>0 1 0 1</ambient>
        </material>
      </visual>
    </link>
    <joint name='rear_right_joint' type='revolute'>
      <pose relative_to='chassis'>-0.5 -0.20000000000000002 0 0 0 0</pose>
      <parent>chassis</parent>
      <child>rear_right_wheel</child>
      <axis>
        <xyz>0 1 0</xyz>
        <limit>
          <lower>-inf</lower>
          <upper>inf</upper>
        </limit>
        <dynamics>
          <spring_reference>0</spring_reference>
          <spring_stiffness>0</spring_stiffness>
        </dynamics>
      </axis>
    </joint>
    <link name='rear_right_wheel'>
      <pose relative_to='rear_right_joint'>0 0 0 0 0 0</pose>
      <inertial>
        <pose>0 0 0 0 0 0</pose>
        <mass>1</mass>
        <inertia>
          <ixx>0.043333000000000003</ixx>
          <ixy>0</ixy>
          <ixz>0</ixz>
          <iyy>0.043333000000000003</iyy>
          <iyz>0</iyz>
          <izz>0.080000000000000002</izz>
        </inertia>
      </inertial>
      <collision name='rear_right_wheel_collision'>
        <pose>0 0 0 1.5708 0 0</pose>
        <geometry>
          <cylinder>
            <length>0.10000000000000001</length>
            <radius>0.20000000000000002</radius>
          </cylinder>
        </geometry>
      </collision>
      <visual name='rear_right_wheel_visual'>
        <pose>0 0 0 1.5708 0 0</pose>
        <geometry>
          <cylinder>
            <length>0.10000000000000001</length>
            <radius>0.20000000000000002</radius>
          </cylinder>
        </geometry>
        <material>
          <diffuse>0 1 0 1</diffuse>
          <ambient>0 1 0 1</ambient>
        </material>
      </visual>
    </link>
    <joint name="front_camera_joint" type="fixed">
      <parent>chassis</parent>
      <child>rover_sensors::camera_link</child>
      <pose relative_to='chassis'>0 0.20000000000000002 0 0 0 0</pose>
    </joint>

    <joint name="imu_joint" type="fixed">
      <parent>chassis</parent>
      <child>rover_sensors::imu_link</child>
      <pose relative_to='chassis'>0.05 0.20000000000000002 0 0 0 0</pose>
    </joint>

    <joint name="lidar_joint" type="fixed">
      <parent>chassis</parent>
      <child>rover_sensors::lidar_link</child>
      <pose relative_to='chassis'>0.1 0.20000000000000002 0 0 0 0</pose>
    </joint>
    

  </model>
</sdf>
