<?xml version="1.0" ?>
<!-- =================================================================================== -->
<!-- |    This document was autogenerated by xacro from robot-localization/urdf/rover.urdf.xacro | -->
<!-- |    EDITING THIS FILE BY HAND IS NOT RECOMMENDED                                 | -->
<!-- =================================================================================== -->
<robot name="rover">
  <link name="chassis">
    <visual>
      <geometry>
        <box size="2.0 1.0 0.5"/>
      </geometry>
      <material name="Black">
        <color rgba="0.0 0.0 1.0 1"/>
      </material>
    </visual>
    <collision>
      <geometry>
        <box size="2.0 1.0 0.5"/>
      </geometry>
    </collision>
    <inertial>
      <mass value="1.14395"/>
      <inertia ixx="0.095329" ixy="0" ixz="0" iyy="0.381317" iyz="0" izz="0.476646"/>
    </inertial>
  </link>
  <!-- generate joints -->
  <link name="front_left_wheel">
    <visual>
      <geometry>
        <cylinder length="0.2" radius="0.4"/>
      </geometry>
      <material name="green">
        <color rgba="0.0 1.0 0.0 1"/>
      </material>
      <origin rpy="1.5708 0 0"/>
    </visual>
    <collision>
      <geometry>
        <cylinder length="0.2" radius="0.4"/>
      </geometry>
    </collision>
    <inertial>
      <mass value="1"/>
      <inertia ixx="0.043333" ixy="0" ixz="0" iyy="0.043333" iyz="0" izz="0.08"/>
    </inertial>
  </link>
  <joint name="front_left_joint" type="continuous">
    <parent link="chassis"/>
    <child link="front_left_wheel"/>
    <origin xyz="0.75 0.4 0"/>
    <axis xyz="0 1 0"/>
  </joint>
  <link name="front_right_wheel">
    <visual>
      <geometry>
        <cylinder length="0.2" radius="0.4"/>
      </geometry>
      <material name="green">
        <color rgba="0.0 1.0 0.0 1"/>
      </material>
      <origin rpy="1.5708 0 0"/>
    </visual>
    <collision>
      <geometry>
        <cylinder length="0.2" radius="0.4"/>
      </geometry>
    </collision>
    <inertial>
      <mass value="1"/>
      <inertia ixx="0.043333" ixy="0" ixz="0" iyy="0.043333" iyz="0" izz="0.08"/>
    </inertial>
  </link>
  <joint name="front_right_joint" type="continuous">
    <parent link="chassis"/>
    <child link="front_right_wheel"/>
    <origin xyz="0.75 -0.4 0"/>
    <axis xyz="0 1 0"/>
  </joint>
  <link name="rear_left_wheel">
    <visual>
      <geometry>
        <cylinder length="0.2" radius="0.4"/>
      </geometry>
      <material name="green">
        <color rgba="0.0 1.0 0.0 1"/>
      </material>
      <origin rpy="1.5708 0 0"/>
    </visual>
    <collision>
      <geometry>
        <cylinder length="0.2" radius="0.4"/>
      </geometry>
    </collision>
    <inertial>
      <mass value="1"/>
      <inertia ixx="0.043333" ixy="0" ixz="0" iyy="0.043333" iyz="0" izz="0.08"/>
    </inertial>
  </link>
  <joint name="rear_left_joint" type="continuous">
    <parent link="chassis"/>
    <child link="rear_left_wheel"/>
    <origin xyz="-0.75 0.4 0"/>
    <axis xyz="0 1 0"/>
  </joint>
  <link name="rear_right_wheel">
    <visual>
      <geometry>
        <cylinder length="0.2" radius="0.4"/>
      </geometry>
      <material name="green">
        <color rgba="0.0 1.0 0.0 1"/>
      </material>
      <origin rpy="1.5708 0 0"/>
    </visual>
    <collision>
      <geometry>
        <cylinder length="0.2" radius="0.4"/>
      </geometry>
    </collision>
    <inertial>
      <mass value="1"/>
      <inertia ixx="0.043333" ixy="0" ixz="0" iyy="0.043333" iyz="0" izz="0.08"/>
    </inertial>
  </link>
  <joint name="rear_right_joint" type="continuous">
    <parent link="chassis"/>
    <child link="rear_right_wheel"/>
    <origin xyz="-0.75 -0.4 0"/>
    <axis xyz="0 1 0"/>
  </joint>
  <!-- generate plugin for camera -->
  <!-- generate plugin for lidar -->
  <!-- generate plugin for imu -->
</robot>
